<?xml version="1.0" encoding="utf-8"?>
<robot name="mmk2">

  <!-- <mujoco>
    <compiler meshdir="../meshes" balanceinertia="true" discardvisual="false" />
  </mujoco> -->

  <link name="world" />
  <joint name="free_base" type="floating">
    <origin rpy="0 0 0" xyz="0 0 0" />
    <parent link="world" />
    <child link="base_link" />
  </joint>

  <link name="base_link">
    <inertial>
      <origin xyz="-0.0400313721989715 -0.0226608008968248 0.756257223317173" rpy="0 0 0" />
      <mass value="33.0267456398628" />
      <inertia ixx="3.44838378637062" ixy="-0.00207943141138886" ixz="-0.0103091786755565" iyy="3.49493780774117" iyz="-0.00146679448998739" izz="0.21980548376876" />
    </inertial>
    <visual>
      <origin xyz="0 0 0" rpy="0 0 0" />
      <geometry>
        <mesh filename="package://mmk2_model/meshes/mmk2/base_link.STL" />
      </geometry>
      <material name="">
        <color rgba="0.752941176470588 0.752941176470588 0.752941176470588 1" />
      </material>
    </visual>
    <collision>
      <origin xyz="0 0 0" rpy="0 0 0" />
      <geometry>
        <mesh filename="package://mmk2_model/meshes/mmk2/base_link.STL" />
      </geometry>
    </collision>
  </link>
  <link name="rgt_wheel_link">
    <inertial>
      <origin xyz="5.20143266670436E-06 5.37603125005695E-07 -0.0018711144360713" rpy="0 0 0" />
      <mass value="1.15656808640541" />
      <inertia ixx="0.0021044922532766" ixy="1.88606601059021E-10" ixz="-3.50324127667933E-07" iyy="0.00210448664280546" iyz="-3.619495141978E-08" izz="0.00355284737378788" />
    </inertial>
    <visual>
      <origin xyz="0 0 0" rpy="0 0 0" />
      <geometry>
        <mesh filename="package://mmk2_model/meshes/mmk2/rgt_wheel_link.STL" />
      </geometry>
      <material name="">
        <color rgba="0.752941176470588 0.752941176470588 0.752941176470588 1" />
      </material>
    </visual>
    <collision>
      <origin xyz="0 0 0" rpy="0 0 0" />
      <geometry>
        <mesh
          filename="package://mmk2_model/meshes/mmk2/rgt_wheel_link.STL" />
      </geometry>
    </collision>
  </link>
  <joint name="rgt_wheel_joint" type="revolute">
    <origin xyz="0 -0.16325 0.08401" rpy="1.5708 1.5708 0" />
    <parent link="base_link" />
    <child link="rgt_wheel_link" />
    <axis xyz="0 0 1" />
    <limit lower="-3.1416" upper="3.1416" effort="6.5" velocity="0.7" />
  </joint>
  <link name="lft_wheel_link">
    <inertial>
      <origin xyz="1.28756699316335E-06 -5.0575586944921E-06 0.00187111444199509" rpy="0 0 0" />
      <mass value="1.15656808621832" />
      <inertia ixx="0.00210448719172768" ixy="-1.67788115008943E-09" ixz="8.7251015028674E-08" iyy="0.00210449170378954" iyz="-3.41206350459015E-07" izz="0.00355284737380655" />
    </inertial>
    <visual>
      <origin xyz="0 0 0" rpy="0 0 0" />
      <geometry>
        <mesh filename="package://mmk2_model/meshes/mmk2/lft_wheel_link.STL" />
      </geometry>
      <material name="">
        <color rgba="0.752941176470588 0.752941176470588 0.752941176470588 1" />
      </material>
    </visual>
    <collision>
      <origin xyz="0 0 0" rpy="0 0 0" />
      <geometry>
        <mesh filename="package://mmk2_model/meshes/mmk2/lft_wheel_link.STL" />
      </geometry>
    </collision>
  </link>
  <joint name="lft_wheel_joint" type="revolute">
    <origin xyz="0 0.16325 0.08401" rpy="1.5708 1.5708 0" />
    <parent link="base_link" />
    <child link="lft_wheel_link" />
    <axis xyz="0 0 1" />
    <limit lower="-3.1416" upper="3.1416" effort="6.5" velocity="0.7" />
  </joint>
  <link name="slide_link">
    <inertial>
      <origin xyz="-7.90494393625066E-05 0.067355217450789 0.10519083626064" rpy="0 0 0" />
      <mass value="2.87043102920673" />
      <inertia ixx="0.00899755064402379" ixy="6.09937870252811E-07" ixz="2.90775161414524E-06" iyy="0.0119634133355932" iyz="-0.000250919444280722" izz="0.00864817587777869" />
    </inertial>
    <visual>
      <origin xyz="0 0 0" rpy="0 0 0" />
      <geometry>
        <mesh filename="package://mmk2_model/meshes/mmk2/slide_link.STL" />
      </geometry>
      <material name="">
        <color rgba="0.752941176470588 0.752941176470588 0.752941176470588 1" />
      </material>
    </visual>
    <collision>
      <origin xyz="0 0 0" rpy="0 0 0" />
      <geometry>
        <mesh filename="package://mmk2_model/meshes/mmk2/slide_link.STL" />
      </geometry>
    </collision>
  </link>
  <joint name="slide_joint" type="prismatic">
    <origin xyz="0.033942 -0.00025 1.406" rpy="3.1416 0 1.5708" />
    <parent link="base_link" />
    <child link="slide_link" />
    <axis xyz="0 0 1" />
    <limit lower="-0.04" upper="0.87" effort="5" velocity="0.3" />
  </joint>
  <link name="head_yaw_link">
    <inertial>
      <origin xyz="0.0118490941462296 0.000491254783341499 0.0390231494943873" rpy="0 0 0" />
      <mass value="0.263127360420809" />
      <inertia  ixx="0.000185798854547827" ixy="2.64309797822853E-07" ixz="-2.93582511724902E-05" iyy="0.000173833362201622" iyz="-2.8054841555532E-06" izz="9.38655776831082E-05" />
    </inertial>
    <visual>
      <origin xyz="0 0 0" rpy="0 0 0" />
      <geometry>
        <mesh filename="package://mmk2_model/meshes/mmk2/head_yaw_link.STL" />
      </geometry>
      <material name="">
        <color rgba="0.752941176470588 0.752941176470588 0.752941176470588 1" />
      </material>
    </visual>
    <collision>
      <origin xyz="0 0 0" rpy="0 0 0" />
      <geometry>
        <mesh filename="package://mmk2_model/meshes/mmk2/head_yaw_link.STL" />
      </geometry>
    </collision>
  </link>
  <joint name="head_yaw_joint" type="revolute">
    <origin xyz="0 0.1735 0.07242" rpy="3.1416 0 0" />
    <parent link="slide_link" />
    <child link="head_yaw_link" />
    <axis xyz="0 0 1" />
    <limit lower="-0.5" upper="0.5" effort="2" velocity="0.2" />
  </joint>
  <link name="head_pitch_link">
    <inertial>
      <origin xyz="0.0244659096221799 -0.108421751901101 -0.00311687659834824" rpy="0 0 0" />
      <mass value="0.500765947013434" />
      <inertia ixx="0.00157924187002826" ixy="2.16781765858799E-05" ixz="-1.02638171835218E-06" iyy="0.000804096450222595" iyz="1.48815549401623E-05" izz="0.00113048749298996" />
    </inertial>
    <visual>
      <origin xyz="0 0 0" rpy="0 0 0" />
      <geometry>
        <mesh filename="package://mmk2_model/meshes/mmk2/head_pitch_link.STL" />
      </geometry>
      <material name="">
        <color rgba="0.752941176470588 0.752941176470588 0.752941176470588 1" />
      </material>
    </visual>
    <collision>
      <origin xyz="0 0 0" rpy="0 0 0" />
      <geometry>
        <mesh filename="package://mmk2_model/meshes/mmk2/head_pitch_link.STL" />
      </geometry>
    </collision>
  </link>
  <joint name="head_pitch_joint" type="revolute">
    <origin xyz="0.00099952 3.1059E-05 0.058" rpy="-1.5708 0 -1.5397" />
    <parent link="head_yaw_link" />
    <child link="head_pitch_link" />
    <axis xyz="0 0 1" />
    <limit lower="-0.16" upper="1.18" effort="2" velocity="0.2" />
  </joint>

  <!-- left arm -->
  <joint name="left_arm_fixed_joint" type="fixed">
    <origin xyz="0.10174 0.02283 0.09475" rpy="1.57079633 0 2.356194490192345"/>
    <parent link="slide_link" />
    <child link="lftarm_base" />
  </joint>
  <link name="lftarm_base">
    <inertial>
      <origin xyz="-0.010729 -0.00017015 0.041712" rpy="0 0 0"/>
      <mass value="0.77705"/>
      <inertia ixx="0.0008454" ixy="-7.5E-06" ixz="2.06E-05" iyy="0.0011821" iyz="-6.4E-06" izz="0.0012443"/>
    </inertial>
    <visual>
      <origin xyz="0 0 0" rpy="0 0 0"/>
      <geometry>
        <mesh filename="package://mmk2_model/meshes/airbot_play/arm_base.STL"/>
      </geometry>
      <material name="">
        <color rgba="0.75294 0.75294 0.75294 1"/>
      </material>
    </visual>
    <collision>
      <origin xyz="0 0 0" rpy="0 0 0"/>
      <geometry>
        <mesh filename="package://mmk2_model/meshes/airbot_play/arm_base.STL"/>
      </geometry>
    </collision>
  </link>
  <link name="lftarm_link1">
    <inertial>
      <origin xyz="7.9126E-05 -0.002527 -0.0041359" rpy="0 0 0"/>
      <mass value="0.54639"/>
      <inertia ixx="0.0003462" ixy="0" ixz="-1.4E-06" iyy="0.0002863" iyz="-1.1E-06" izz="0.0003255"/>
    </inertial>
    <visual>
      <origin xyz="0 0 0" rpy="0 0 0"/>
      <geometry>
        <mesh filename="package://mmk2_model/meshes/airbot_play/link1.STL"/>
      </geometry>
      <material name="">
        <color rgba="0.89804 0.91765 0.92941 1"/>
      </material>
    </visual>
    <collision>
      <origin xyz="0 0 0" rpy="0 0 0"/>
      <geometry>
        <mesh filename="package://mmk2_model/meshes/airbot_play/link1.STL"/>
      </geometry>
    </collision>
  </link>
  <joint name="lftarm_joint1" type="revolute">
    <origin xyz="0 0 0.1172" rpy="0 0 0"/>
    <parent link="lftarm_base"/>
    <child link="lftarm_link1"/>
    <axis xyz="0 0 1"/>
    <limit lower="-3.14" upper="2.09" effort="18" velocity="3.14"/>
  </joint>
  <link name="lftarm_link2">
    <inertial>
      <origin xyz="0.22493 0.0047721 0.008023" rpy="0 0 0"/>
      <mass value="0.64621"/>
      <inertia ixx="0.0004901" ixy="0.0005229" ixz="-0.0002434" iyy="0.0050391" iyz="-2.95E-05" izz="0.0051052"/>
    </inertial>
    <visual>
      <origin xyz="0 0 0" rpy="0 0 0"/>
      <geometry>
        <mesh filename="package://mmk2_model/meshes/airbot_play/link2.STL"/>
      </geometry>
      <material name="">
        <color rgba="0.75294 0.75294 0.75294 1"/>
      </material>
    </visual>
    <collision>
      <origin xyz="0 0 0" rpy="0 0 0"/>
      <geometry>
        <mesh filename="package://mmk2_model/meshes/airbot_play/link2.STL"/>
      </geometry>
    </collision>
  </link>
  <joint name="lftarm_joint2" type="revolute">
    <origin xyz="0 0 0" rpy="1.5708 -2.7549 0"/>
    <parent link="lftarm_link1"/>
    <child link="lftarm_link2"/>
    <axis xyz="0 0 1"/>
    <limit lower="-2.96" upper="0.17" effort="18" velocity="3.14"/>
  </joint>
  <link name="lftarm_link3">
    <inertial>
      <origin xyz="0.16813 -5.5576E-05 0.0031184" rpy="0 0 0"/>
      <mass value="0.26829"/>
      <inertia ixx="0.000245" ixy="-4E-07" ixz="-0.0001263" iyy="0.0031527" iyz="-1E-07" izz="0.0030895"/>
    </inertial>
    <visual>
      <origin xyz="0 0 0" rpy="0 0 0"/>
      <geometry>
        <mesh filename="package://mmk2_model/meshes/airbot_play/link3.STL"/>
      </geometry>
      <material name="">
        <color rgba="0.75294 0.75294 0.75294 1"/>
      </material>
    </visual>
    <collision>
      <origin xyz="0 0 0" rpy="0 0 0"/>
      <geometry>
        <mesh filename="package://mmk2_model/meshes/airbot_play/link3.STL"/>
      </geometry>
    </collision>
  </link>
  <joint name="lftarm_joint3" type="revolute">
    <origin xyz="0.27009 0 0" rpy="0 0 -2.7549"/>
    <parent link="lftarm_link2"/>
    <child link="lftarm_link3"/>
    <axis xyz="0 0 1"/>
    <limit lower="-0.087" upper="3.14" effort="18" velocity="3.14"/>
  </joint>
  <link name="lftarm_link4">
    <inertial>
      <origin xyz="5.2436E-06 0.00040412 -0.03228" rpy="0 0 0"/>
      <mass value="0.34876"/>
      <inertia ixx="0.0004235" ixy="0" ixz="4.7E-06" iyy="0.000412" iyz="-1E-07" izz="0.0001269"/>
    </inertial>
    <visual>
      <origin xyz="0 0 0" rpy="0 0 0"/>
      <geometry>
        <mesh filename="package://mmk2_model/meshes/airbot_play/link4.STL"/>
      </geometry>
      <material name="">
        <color rgba="1 1 1 1"/>
      </material>
    </visual>
    <collision>
      <origin xyz="0 0 0" rpy="0 0 0"/>
      <geometry>
        <mesh filename="package://mmk2_model/meshes/airbot_play/link4.STL"/>
      </geometry>
    </collision>
  </link>
  <joint name="lftarm_joint4" type="revolute">
    <origin xyz="0.29015 0 0" rpy="3.1416 -1.5708 0"/>
    <parent link="lftarm_link3"/>
    <child link="lftarm_link4"/>
    <axis xyz="0 0 1"/>
    <limit lower="-2.96" upper="2.96" effort="3" velocity="6.28"/>
  </joint>
  <link name="lftarm_link5">
    <inertial>
      <origin xyz="8.3328E-06 0.026148 0.002525" rpy="0 0 0"/>
      <mass value="0.36132"/>
      <inertia ixx="0.0001825" ixy="0" ixz="-3.29E-05" iyy="0.0004677" iyz="0" izz="0.0004286"/>
    </inertial>
    <visual>
      <origin xyz="0 0 0" rpy="0 0 0"/>
      <geometry>
        <mesh filename="package://mmk2_model/meshes/airbot_play/link5.STL"/>
      </geometry>
      <material name="">
        <color rgba="0.89804 0.91765 0.92941 1"/>
      </material>
    </visual>
    <collision>
      <origin xyz="0 0 0" rpy="0 0 0"/>
      <geometry>
        <mesh filename="package://mmk2_model/meshes/airbot_play/link5.STL"/>
      </geometry>
    </collision>
  </link>
  <joint name="lftarm_joint5" type="revolute">
    <origin xyz="0 0 0" rpy="1.5708 0 0"/>
    <parent link="lftarm_link4"/>
    <child link="lftarm_link5"/>
    <axis xyz="0 0 1"/>
    <limit lower="-1.74" upper="1.74" effort="3" velocity="6.28"/>
  </joint>
  <link name="lftarm_link6">
    <inertial>
      <origin xyz="-0.0047053 7.3857E-05 -0.12293" rpy="0 0 0"/>
      <mass value="0.53855"/>
      <inertia ixx="5E-05" ixy="0" ixz="0" iyy="5E-05" iyz="0" izz="3.85E-05"/>
    </inertial>
    <visual>
      <origin xyz="0 0 0" rpy="0 0 0"/>
      <geometry>
        <mesh filename="package://mmk2_model/meshes/airbot_play/link6.STL"/>
      </geometry>
      <material name="">
        <color rgba="0.69804 0.69804 0.69804 1"/>
      </material>
    </visual>
    <collision>
      <origin xyz="0 0 0" rpy="0 0 0"/>
      <geometry>
        <mesh filename="package://mmk2_model/meshes/airbot_play/link6.STL"/>
      </geometry>
    </collision>
  </link>
  <joint name="lftarm_joint6" type="revolute">
    <origin xyz="0 0.23645 0" rpy="-1.5708 1.5708 0"/>
    <parent link="lftarm_link5"/>
    <child link="lftarm_link6"/>
    <axis xyz="0 0 1"/>
    <limit lower="-3.14" upper="3.14" effort="3" velocity="6.28"/>
  </joint>
  <link name="lftarm_left">
    <inertial>
      <origin xyz="-0.049039 -0.0096764 0.00038868" rpy="0 0 0"/>
      <mass value="0.061803"/>
      <inertia ixx="1.8946E-05" ixy="-1.3168E-06" ixz="-6.5528E-07" iyy="2.7277E-05" iyz="-2.0801E-07" izz="1.1981E-05"/>
    </inertial>
    <visual>
      <origin xyz="0 0 0" rpy="0 0 0"/>
      <geometry>
        <mesh filename="package://mmk2_model/meshes/airbot_play/left.STL"/>
      </geometry>
      <material name="">
        <color rgba="1 1 1 1"/>
      </material>
    </visual>
    <collision>
      <origin xyz="0 0 0" rpy="0 0 0"/>
      <geometry>
        <mesh filename="package://mmk2_model/meshes/airbot_play/left.STL"/>
      </geometry>
    </collision>
  </link>
  <joint name="lftarm_endleft" type="prismatic">
    <origin xyz="0 0.003 0" rpy="3.14159 -1.5708 0"/>
    <parent link="lftarm_link6"/>
    <child link="lftarm_left"/>
    <axis xyz="0 1 0"/>
    <limit lower="-0.04" upper="0" effort="0" velocity="0"/>
  </joint>
  <link name="lftarm_right">
    <inertial>
      <origin xyz="-0.048742 0.0096369 0.00044322" rpy="0 0 0"/>
      <mass value="0.0626"/>
      <inertia ixx="1.915E-05" ixy="1.343E-06" ixz="-6.8259E-07" iyy="2.7722E-05" iyz="2.0748E-07" izz="1.2248E-05"/>
    </inertial>
    <visual>
      <origin xyz="0 0 0" rpy="0 0 0"/>
      <geometry>
        <mesh filename="package://mmk2_model/meshes/airbot_play/right.STL"/>
      </geometry>
      <material name="">
        <color rgba="1 1 1 1"/>
      </material>
    </visual>
    <collision>
      <origin xyz="0 0 0" rpy="0 0 0"/>
      <geometry>
        <mesh filename="package://mmk2_model/meshes/airbot_play/right.STL"/>
      </geometry>
    </collision>
  </link>
  <joint name="lftarm_endright" type="prismatic">
    <origin xyz="0 -0.003 0" rpy="3.14159 -1.5708 0"/>
    <parent link="lftarm_link6"/>
    <child link="lftarm_right"/>
    <axis xyz="0 1 0"/>
    <limit lower="0" upper="0.04" effort="0" velocity="0"/>
  </joint>
  <link name="lftarm_custom_end_link">
      <inertial>
          <origin xyz="0 0 0" rpy="0 0 0"/>
          <mass value="1E-15"/>
          <inertia ixx="1E-11" ixy="1E-15" ixz="1E-15" iyy="1E-11" iyz="1E-15" izz="1E-11"/>
      </inertial>
  </link>
  <joint name="lftarm_joint_custom_end" type="fixed">
      <origin xyz="0 0 0.02" rpy="0 -1.5708 0"/>
      <parent link="lftarm_link6"/>
      <child link="lftarm_custom_end_link"/>
  </joint>

  <!-- right arm -->
  <joint name="right_arm_fixed_joint" type="fixed">
    <origin xyz="-0.10174 0.02283 0.09475" rpy="-1.57079633 0 0.7853981633974483"/>
    <parent link="slide_link" />
    <child link="rgtarm_base" />
  </joint>
  <link name="rgtarm_base">
    <inertial>
      <origin xyz="-0.010729 -0.00017015 0.041712" rpy="0 0 0"/>
      <mass value="0.77705"/>
      <inertia ixx="0.0008454" ixy="-7.5E-06" ixz="2.06E-05" iyy="0.0011821" iyz="-6.4E-06" izz="0.0012443"/>
    </inertial>
    <visual>
      <origin xyz="0 0 0" rpy="0 0 0"/>
      <geometry>
        <mesh filename="package://mmk2_model/meshes/airbot_play/arm_base.STL"/>
      </geometry>
      <material name="">
        <color rgba="0.75294 0.75294 0.75294 1"/>
      </material>
    </visual>
    <collision>
      <origin xyz="0 0 0" rpy="0 0 0"/>
      <geometry>
        <mesh filename="package://mmk2_model/meshes/airbot_play/arm_base.STL"/>
      </geometry>
    </collision>
  </link>
  <link name="rgtarm_link1">
    <inertial>
      <origin xyz="7.9126E-05 -0.002527 -0.0041359" rpy="0 0 0"/>
      <mass value="0.54639"/>
      <inertia ixx="0.0003462" ixy="0" ixz="-1.4E-06" iyy="0.0002863" iyz="-1.1E-06" izz="0.0003255"/>
    </inertial>
    <visual>
      <origin xyz="0 0 0" rpy="0 0 0"/>
      <geometry>
        <mesh filename="package://mmk2_model/meshes/airbot_play/link1.STL"/>
      </geometry>
      <material name="">
        <color rgba="0.89804 0.91765 0.92941 1"/>
      </material>
    </visual>
    <collision>
      <origin xyz="0 0 0" rpy="0 0 0"/>
      <geometry>
        <mesh filename="package://mmk2_model/meshes/airbot_play/link1.STL"/>
      </geometry>
    </collision>
  </link>
  <joint name="rgtarm_joint1" type="revolute">
    <origin xyz="0 0 0.1172" rpy="0 0 0"/>
    <parent link="rgtarm_base"/>
    <child link="rgtarm_link1"/>
    <axis xyz="0 0 1"/>
    <limit lower="-3.14" upper="2.09" effort="18" velocity="3.14"/>
  </joint>
  <link name="rgtarm_link2">
    <inertial>
      <origin xyz="0.22493 0.0047721 0.008023" rpy="0 0 0"/>
      <mass value="0.64621"/>
      <inertia ixx="0.0004901" ixy="0.0005229" ixz="-0.0002434" iyy="0.0050391" iyz="-2.95E-05" izz="0.0051052"/>
    </inertial>
    <visual>
      <origin xyz="0 0 0" rpy="0 0 0"/>
      <geometry>
        <mesh filename="package://mmk2_model/meshes/airbot_play/link2.STL"/>
      </geometry>
      <material name="">
        <color rgba="0.75294 0.75294 0.75294 1"/>
      </material>
    </visual>
    <collision>
      <origin xyz="0 0 0" rpy="0 0 0"/>
      <geometry>
        <mesh filename="package://mmk2_model/meshes/airbot_play/link2.STL"/>
      </geometry>
    </collision>
  </link>
  <joint name="rgtarm_joint2" type="revolute">
    <origin xyz="0 0 0" rpy="1.5708 -2.7549 0"/>
    <parent link="rgtarm_link1"/>
    <child link="rgtarm_link2"/>
    <axis xyz="0 0 1"/>
    <limit lower="-2.96" upper="0.17" effort="18" velocity="3.14"/>
  </joint>
  <link name="rgtarm_link3">
    <inertial>
      <origin xyz="0.16813 -5.5576E-05 0.0031184" rpy="0 0 0"/>
      <mass value="0.26829"/>
      <inertia ixx="0.000245" ixy="-4E-07" ixz="-0.0001263" iyy="0.0031527" iyz="-1E-07" izz="0.0030895"/>
    </inertial>
    <visual>
      <origin xyz="0 0 0" rpy="0 0 0"/>
      <geometry>
        <mesh filename="package://mmk2_model/meshes/airbot_play/link3.STL"/>
      </geometry>
      <material name="">
        <color rgba="0.75294 0.75294 0.75294 1"/>
      </material>
    </visual>
    <collision>
      <origin xyz="0 0 0" rpy="0 0 0"/>
      <geometry>
        <mesh filename="package://mmk2_model/meshes/airbot_play/link3.STL"/>
      </geometry>
    </collision>
  </link>
  <joint name="rgtarm_joint3" type="revolute">
    <origin xyz="0.27009 0 0" rpy="0 0 -2.7549"/>
    <parent link="rgtarm_link2"/>
    <child link="rgtarm_link3"/>
    <axis xyz="0 0 1"/>
    <limit lower="-0.087" upper="3.14" effort="18" velocity="3.14"/>
  </joint>
  <link name="rgtarm_link4">
    <inertial>
      <origin xyz="5.2436E-06 0.00040412 -0.03228" rpy="0 0 0"/>
      <mass value="0.34876"/>
      <inertia ixx="0.0004235" ixy="0" ixz="4.7E-06" iyy="0.000412" iyz="-1E-07" izz="0.0001269"/>
    </inertial>
    <visual>
      <origin xyz="0 0 0" rpy="0 0 0"/>
      <geometry>
        <mesh filename="package://mmk2_model/meshes/airbot_play/link4.STL"/>
      </geometry>
      <material name="">
        <color rgba="1 1 1 1"/>
      </material>
    </visual>
    <collision>
      <origin xyz="0 0 0" rpy="0 0 0"/>
      <geometry>
        <mesh filename="package://mmk2_model/meshes/airbot_play/link4.STL"/>
      </geometry>
    </collision>
  </link>
  <joint name="rgtarm_joint4" type="revolute">
    <origin xyz="0.29015 0 0" rpy="3.1416 -1.5708 0"/>
    <parent link="rgtarm_link3"/>
    <child link="rgtarm_link4"/>
    <axis xyz="0 0 1"/>
    <limit lower="-2.96" upper="2.96" effort="3" velocity="6.28"/>
  </joint>
  <link name="rgtarm_link5">
    <inertial>
      <origin xyz="8.3328E-06 0.026148 0.002525" rpy="0 0 0"/>
      <mass value="0.36132"/>
      <inertia ixx="0.0001825" ixy="0" ixz="-3.29E-05" iyy="0.0004677" iyz="0" izz="0.0004286"/>
    </inertial>
    <visual>
      <origin xyz="0 0 0" rpy="0 0 0"/>
      <geometry>
        <mesh filename="package://mmk2_model/meshes/airbot_play/link5.STL"/>
      </geometry>
      <material name="">
        <color rgba="0.89804 0.91765 0.92941 1"/>
      </material>
    </visual>
    <collision>
      <origin xyz="0 0 0" rpy="0 0 0"/>
      <geometry>
        <mesh filename="package://mmk2_model/meshes/airbot_play/link5.STL"/>
      </geometry>
    </collision>
  </link>
  <joint name="rgtarm_joint5" type="revolute">
    <origin xyz="0 0 0" rpy="1.5708 0 0"/>
    <parent link="rgtarm_link4"/>
    <child link="rgtarm_link5"/>
    <axis xyz="0 0 1"/>
    <limit lower="-1.74" upper="1.74" effort="3" velocity="6.28"/>
  </joint>
  <link name="rgtarm_link6">
    <inertial>
      <origin xyz="-0.0047053 7.3857E-05 -0.12293" rpy="0 0 0"/>
      <mass value="0.53855"/>
      <inertia ixx="5E-05" ixy="0" ixz="0" iyy="5E-05" iyz="0" izz="3.85E-05"/>
    </inertial>
    <visual>
      <origin xyz="0 0 0" rpy="0 0 0"/>
      <geometry>
        <mesh filename="package://mmk2_model/meshes/airbot_play/link6.STL"/>
      </geometry>
      <material name="">
        <color rgba="0.69804 0.69804 0.69804 1"/>
      </material>
    </visual>
    <collision>
      <origin xyz="0 0 0" rpy="0 0 0"/>
      <geometry>
        <mesh filename="package://mmk2_model/meshes/airbot_play/link6.STL"/>
      </geometry>
    </collision>
  </link>
  <joint name="rgtarm_joint6" type="revolute">
    <origin xyz="0 0.23645 0" rpy="-1.5708 1.5708 0"/>
    <parent link="rgtarm_link5"/>
    <child link="rgtarm_link6"/>
    <axis xyz="0 0 1"/>
    <limit lower="-3.14" upper="3.14" effort="3" velocity="6.28"/>
  </joint>
  <link name="rgtarm_left">
    <inertial>
      <origin xyz="-0.049039 -0.0096764 0.00038868" rpy="0 0 0"/>
      <mass value="0.061803"/>
      <inertia ixx="1.8946E-05" ixy="-1.3168E-06" ixz="-6.5528E-07" iyy="2.7277E-05" iyz="-2.0801E-07" izz="1.1981E-05"/>
    </inertial>
    <visual>
      <origin xyz="0 0 0" rpy="0 0 0"/>
      <geometry>
        <mesh filename="package://mmk2_model/meshes/airbot_play/left.STL"/>
      </geometry>
      <material name="">
        <color rgba="1 1 1 1"/>
      </material>
    </visual>
    <collision>
      <origin xyz="0 0 0" rpy="0 0 0"/>
      <geometry>
        <mesh filename="package://mmk2_model/meshes/airbot_play/left.STL"/>
      </geometry>
    </collision>
  </link>
  <joint name="rgtarm_endleft" type="prismatic">
    <origin xyz="0 0.003 0" rpy="3.14159 -1.5708 0"/>
    <parent link="rgtarm_link6"/>
    <child link="rgtarm_left"/>
    <axis xyz="0 1 0"/>
    <limit lower="-0.04" upper="0" effort="0" velocity="0"/>
  </joint>
  <link name="rgtarm_right">
    <inertial>
      <origin xyz="-0.048742 0.0096369 0.00044322" rpy="0 0 0"/>
      <mass value="0.0626"/>
      <inertia ixx="1.915E-05" ixy="1.343E-06" ixz="-6.8259E-07" iyy="2.7722E-05" iyz="2.0748E-07" izz="1.2248E-05"/>
    </inertial>
    <visual>
      <origin xyz="0 0 0" rpy="0 0 0"/>
      <geometry>
        <mesh filename="package://mmk2_model/meshes/airbot_play/right.STL"/>
      </geometry>
      <material name="">
        <color rgba="1 1 1 1"/>
      </material>
    </visual>
    <collision>
      <origin xyz="0 0 0" rpy="0 0 0"/>
      <geometry>
        <mesh filename="package://mmk2_model/meshes/airbot_play/right.STL"/>
      </geometry>
    </collision>
  </link>
  <joint name="rgtarm_endright" type="prismatic">
    <origin xyz="0 -0.003 0" rpy="3.14159 -1.5708 0"/>
    <parent link="rgtarm_link6"/>
    <child link="rgtarm_right"/>
    <axis xyz="0 1 0"/>
    <limit lower="0" upper="0.04" effort="0" velocity="0"/>
  </joint>
  <link name="rgtarm_custom_end_link">
      <inertial>
          <origin xyz="0 0 0" rpy="0 0 0"/>
          <mass value="1E-15"/>
          <inertia ixx="1E-11" ixy="1E-15" ixz="1E-15" iyy="1E-11" iyz="1E-15" izz="1E-11"/>
      </inertial>
  </link>
  <joint name="rgtarm_joint_custom_end" type="fixed">
      <origin xyz="0 0 0.02" rpy="0 -1.5708 0"/>
      <parent link="rgtarm_link6"/>
      <child link="rgtarm_custom_end_link"/>
  </joint>
</robot>